<?xml version="1.0" encoding="UTF-8"?>
<testsuite name="Test"
           tests="7"
           failures="1"
           errors="0"
           skipped="0"
           time="0.011">
  <properties />
            <testcase name="sixth_testcase" time="0.004" classname="testNGDemo.TestScenario12">
                <failure type="java.lang.AssertionError"
                  message="expected [Hello1] but found [Hello]"
              >
<![CDATA[java.lang.AssertionError: expected [Hello1] but found [Hello]
  org.testng.Assert.fail(Assert.java:111)
  org.testng.Assert.failNotEquals(Assert.java:1578)
  org.testng.Assert.assertEqualsImpl(Assert.java:150)
  org.testng.Assert.assertEquals(Assert.java:132)
  org.testng.Assert.assertEquals(Assert.java:656)
  org.testng.Assert.assertEquals(Assert.java:666)
  testNGDemo.TestScenario12.sixth_testcase(TestScenario12.java:45)
  java.base/jdk.internal.reflect.NativeMethodAccessorImpl.invoke0(Native Method)
  java.base/jdk.internal.reflect.NativeMethodAccessorImpl.invoke(NativeMethodAccessorImpl.java:77)
  java.base/jdk.internal.reflect.DelegatingMethodAccessorImpl.invoke(DelegatingMethodAccessorImpl.java:43)
  java.base/java.lang.reflect.Method.invoke(Method.java:568)
  org.testng.internal.invokers.MethodInvocationHelper.invokeMethod(MethodInvocationHelper.java:139)
  org.testng.internal.invokers.TestInvoker.invokeMethod(TestInvoker.java:664)
  org.testng.internal.invokers.TestInvoker.invokeTestMethod(TestInvoker.java:227)
  org.testng.internal.invokers.MethodRunner.runInSequence(MethodRunner.java:50)
  org.testng.internal.invokers.TestInvoker$MethodInvocationAgent.invoke(TestInvoker.java:957)
  org.testng.internal.invokers.TestInvoker.invokeTestMethods(TestInvoker.java:200)
  org.testng.internal.invokers.TestMethodWorker.invokeTestMethods(TestMethodWorker.java:148)
  org.testng.internal.invokers.TestMethodWorker.run(TestMethodWorker.java:128)
  java.base/java.util.ArrayList.forEach(ArrayList.java:1511)
  org.testng.TestRunner.privateRun(TestRunner.java:848)
  org.testng.TestRunner.run(TestRunner.java:621)
  org.testng.SuiteRunner.runTest(SuiteRunner.java:443)
  org.testng.SuiteRunner.runSequentially(SuiteRunner.java:437)
  org.testng.SuiteRunner.privateRun(SuiteRunner.java:397)
  org.testng.SuiteRunner.run(SuiteRunner.java:336)
  org.testng.SuiteRunnerWorker.runSuite(SuiteRunnerWorker.java:52)
  org.testng.SuiteRunnerWorker.run(SuiteRunnerWorker.java:95)
  org.testng.TestNG.runSuitesSequentially(TestNG.java:1280)
  org.testng.TestNG.runSuitesLocally(TestNG.java:1200)
  org.testng.TestNG.runSuites(TestNG.java:1114)
  org.testng.TestNG.run(TestNG.java:1082)
  org.testng.remote.AbstractRemoteTestNG.run(AbstractRemoteTestNG.java:115)
  org.testng.remote.RemoteTestNG.initAndRun(RemoteTestNG.java:251)
  org.testng.remote.RemoteTestNG.main(RemoteTestNG.java:77)
]]>
      </failure>

          </testcase>
  
  
            <testcase name="second_testcase" time="0.001" classname="testNGDemo.TestScenario12" />
                <testcase name="seventh_testcase" time="0.002" classname="testNGDemo.TestScenario12" />
                <testcase name="first_testcase" time="0.001" classname="testNGDemo.TestScenario12" />
                <testcase name="fifth_testcase" time="0.001" classname="testNGDemo.TestScenario12" />
                <testcase name="third_testcase" time="0.002" classname="testNGDemo.TestScenario12" />
                <testcase name="forth_testcase" time="0.000" classname="testNGDemo.TestScenario12" />
      
</testsuite>
